<?xml version="1.0" encoding="UTF-8"?>
<!-- =================================================================================== -->
<!-- | This document was autogenerated by xacro from spot.urdf.xacro | -->
<!-- | EDITING THIS FILE BY HAND IS NOT RECOMMENDED | -->
<!-- =================================================================================== -->
<robot name="spot">
  <material name="yellow">
        <color rgba="0.05 0.5 0.0 1.0"/>
   </material>
   <link name="body">
      <visual>
         <geometry>
            <mesh filename="meshes/body.dae" />
         </geometry>
      </visual>
      <collision>
         <geometry>
            <mesh filename="meshes/body_collision.stl" />
         </geometry>
      </collision>
      <inertial>
         <mass value="16.0" />
         <inertia ixx="0.0973333333333" ixy="0.0" ixz="0.0" iyy="1.02466666667" iyz="0.0" izz="1.04493333333" />
      </inertial>
   </link>
   <link name="base_link" />
   <joint name="base_link_joint" type="fixed">
      <origin rpy="0 0 0" xyz="0 0 0" />
      <parent link="body" />
      <child link="base_link" />
   </joint>
   <link name="front_rail" />
   <joint name="front_rail_joint" type="fixed">
      <origin rpy="0 0 0" xyz="0.223 0 0.0805" />
      <parent link="body" />
      <child link="front_rail" />
   </joint>
   <link name="rear_rail" />
   <joint name="rear_rail_joint" type="fixed">
      <origin rpy="0 0 0" xyz="-0.223 0 0.0805" />
      <parent link="body" />
      <child link="rear_rail" />
   </joint>
   <!-- This file is a placeholder which is included by default from
 spot.urdf.xacro. If a robot is being customized and requires
 additional URDF, set the SPOT_URDF_EXTRAS environment variable
 to the full path of the file you would like included. -->
   
   <link name="imu_link">
      <inertial>
         <mass value="0.001" />
         <origin rpy="0 0 0" xyz="0 0 0" />
         <inertia ixx="1e-09" ixy="0.0" ixz="0.0" iyy="1e-09" iyz="0.0" izz="1e-09" />
      </inertial>
   </link>
   <joint name="imu_joint" type="fixed">
      <parent link="base_link" />
      <child link="imu_link" />
   </joint>
   <!-- <xacro:include filename="$(find velodyne_description)/urdf/VLP-16.urdf.xacro"/>
 <xacro:VLP-16 parent="base_link" name="velodyne" topic="velodyne_points" hz="10" samples="1024" gpu="false" lasers="16" max_range="100">
 <origin xyz="0.29 0 ${(base_height / 2) - 0.01}" rpy="0 0 0" />
 </xacro:VLP-16> -->
   <link name="front_left_hip">
      <visual>
         <geometry>
            <mesh filename="meshes/front_left_hip.dae" />
         </geometry>
      </visual>
      <collision>
         <geometry>
            <mesh filename="meshes/front_left_hip_collision.stl" />
         </geometry>
      </collision>
      <inertial>
         <mass value="2.0" />
         <inertia ixx="0.0027" ixy="0.0" ixz="0.0" iyy="0.00416666666667" iyz="0.0" izz="0.00416666666667" />
      </inertial>
   </link>
   <joint name="front_left_hip_x" type="revolute">
      <origin rpy="0 0 0" xyz="0.29785 0.055 0" />
      <axis xyz="1 0 0" />
      <parent link="body" />
      <child link="front_left_hip" />
      <limit effort="100" lower="-0.78539816339744827899" upper="0.78539816339744827899" velocity="1000.00" />
   </joint>
   <link name="front_left_upper_leg">
      <visual>
         <geometry>
            <mesh filename="meshes/front_left_upper_leg.dae" />
         </geometry>
      </visual>
      <collision>
         <geometry>
            <mesh filename="meshes/front_left_upper_leg_collision.stl" />
         </geometry>
      </collision>
      <inertial>
         <origin rpy="0 0 0" xyz="0 0 -0.14" />
         <mass value="1.0" />
         <inertia ixx="0.0155334166667" ixy="0.0" ixz="0.0" iyy="0.0155334166667" iyz="0.0" izz="0.000962666666667" />
      </inertial>
   </link>
   <joint name="front_left_hip_y" type="revolute">
      <origin rpy="0 0 0" xyz="0 0.110945 0" />
      <axis xyz="0 1 0" />
      <parent link="front_left_hip" />
      <child link="front_left_upper_leg" />
      <limit effort="100" lower="-0.89884456477707963539" upper="2.2951079663725435509" velocity="1000.00" />
   </joint>
   <link name="front_left_lower_leg">
      <visual>
         <geometry>
            <mesh filename="meshes/front_left_lower_leg.dae" />
         </geometry>
      </visual>
      <collision>
         <geometry>
            <mesh filename="meshes/front_left_lower_leg_collision.stl" scale="0.82 0.97 0.98" />
         </geometry>
      </collision>
      <inertial>
         <origin rpy="0 0 0" xyz="0 0 -0.16" />
         <mass value="0.5" />
         <inertia ixx="0.007434375" ixy="0.0" ixz="0.0" iyy="0.00740104166667" iyz="0.0" izz="0.000135416666667" />
      </inertial>
   </link>
   <gazebo reference="front_left_lower_leg">
      <kp>100000.0</kp>
      <kd>1.0</kd>
      <mu1>0.8</mu1>
      <mu2>0.8</mu2>
      <maxVel>0.0</maxVel>
      <minDepth>0.001</minDepth>
   </gazebo>
   <joint name="front_left_knee" type="revolute">
      <origin rpy="0 0 0" xyz="0.025 0 -0.3205" />
      <axis xyz="0 1 0" />
      <parent link="front_left_upper_leg" />
      <child link="front_left_lower_leg" />
      <limit effort="100" lower="-2.7929" upper="-0.254801" velocity="1000.00" />
   </joint>
   <link name="front_left_ee" />
   <joint name="front_left_foot" type="fixed">
      <parent link="front_left_lower_leg" />
      <child link="front_left_ee" />
      <origin rpy="0 0 0" xyz="0 0 -0.37" />
   </joint>
   <transmission name="front_left_hip_x_trans">
      <type>transmission_interface/SimpleTransmission</type>
      <joint name="front_left_hip_x">
         <hardwareInterface>hardware_interface/EffortJointInterface</hardwareInterface>
      </joint>
      <actuator name="front_left_hip_x_actuator">
         <hardwareInterface>hardware_interface/EffortJointInterface</hardwareInterface>
         <mechanicalReduction>1</mechanicalReduction>
      </actuator>
   </transmission>
   <transmission name="front_left_hip_y_trans">
      <type>transmission_interface/SimpleTransmission</type>
      <joint name="front_left_hip_y">
         <hardwareInterface>hardware_interface/EffortJointInterface</hardwareInterface>
      </joint>
      <actuator name="front_left_hip_y_actuator">
         <hardwareInterface>hardware_interface/EffortJointInterface</hardwareInterface>
         <mechanicalReduction>1</mechanicalReduction>
      </actuator>
   </transmission>
   <transmission name="front_left_knee_trans">
      <type>transmission_interface/SimpleTransmission</type>
      <joint name="front_left_knee">
         <hardwareInterface>hardware_interface/EffortJointInterface</hardwareInterface>
      </joint>
      <actuator name="front_left_knee_actuator">
         <hardwareInterface>hardware_interface/EffortJointInterface</hardwareInterface>
         <mechanicalReduction>1</mechanicalReduction>
      </actuator>
   </transmission>
   <link name="front_right_hip">
      <visual>
         <geometry>
            <mesh filename="meshes/front_right_hip.dae" />
         </geometry>
      </visual>
      <collision>
         <geometry>
            <mesh filename="meshes/front_right_hip_collision.stl" />
         </geometry>
      </collision>
      <inertial>
         <mass value="2.0" />
         <inertia ixx="0.0027" ixy="0.0" ixz="0.0" iyy="0.00416666666667" iyz="0.0" izz="0.00416666666667" />
      </inertial>
   </link>
   <joint name="front_right_hip_x" type="revolute">
      <origin rpy="0 0 0" xyz="0.29785 -0.055 0" />
      <axis xyz="1 0 0" />
      <parent link="body" />
      <child link="front_right_hip" />
      <limit effort="100" lower="-0.78539816339744827899" upper="0.78539816339744827899" velocity="1000.00" />
   </joint>
   <link name="front_right_upper_leg">
      <visual>
         <geometry>
            <mesh filename="meshes/front_right_upper_leg.dae" />
         </geometry>
      </visual>
      <collision>
         <geometry>
            <mesh filename="meshes/front_right_upper_leg_collision.stl" />
         </geometry>
      </collision>
      <inertial>
         <origin rpy="0 0 0" xyz="0 0 -0.14" />
         <mass value="1.0" />
         <inertia ixx="0.0155334166667" ixy="0.0" ixz="0.0" iyy="0.0155334166667" iyz="0.0" izz="0.000962666666667" />
      </inertial>
   </link>
   <joint name="front_right_hip_y" type="revolute">
      <origin rpy="0 0 0" xyz="0 -0.110945 0" />
      <axis xyz="0 1 0" />
      <parent link="front_right_hip" />
      <child link="front_right_upper_leg" />
      <limit effort="100" lower="-0.89884456477707963539" upper="2.2951079663725435509" velocity="1000.00" />
   </joint>
   <link name="front_right_lower_leg">
      <visual>
         <geometry>
            <mesh filename="meshes/front_right_lower_leg.dae" />
         </geometry>
      </visual>
      <collision>
         <geometry>
            <mesh filename="meshes/front_right_lower_leg_collision.stl" scale="0.82 0.97 0.98" />
         </geometry>
      </collision>
      <inertial>
         <origin rpy="0 0 0" xyz="0 0 -0.16" />
         <mass value="0.5" />
         <inertia ixx="0.007434375" ixy="0.0" ixz="0.0" iyy="0.00740104166667" iyz="0.0" izz="0.000135416666667" />
      </inertial>
   </link>
   <gazebo reference="front_right_lower_leg">
      <kp>100000.0</kp>
      <kd>1.0</kd>
      <mu1>0.8</mu1>
      <mu2>0.8</mu2>
      <maxVel>0.0</maxVel>
      <minDepth>0.001</minDepth>
   </gazebo>
   <joint name="front_right_knee" type="revolute">
      <origin rpy="0 0 0" xyz="0.025 0 -0.3205" />
      <axis xyz="0 1 0" />
      <parent link="front_right_upper_leg" />
      <child link="front_right_lower_leg" />
      <limit effort="100" lower="-2.7929" upper="-0.254801" velocity="1000.00" />
   </joint>
   <link name="front_right_ee" />
   <joint name="front_right_foot" type="fixed">
      <parent link="front_right_lower_leg" />
      <child link="front_right_ee" />
      <origin rpy="0 0 0" xyz="0 0 -0.37" />
   </joint>
   <transmission name="front_right_hip_x_trans">
      <type>transmission_interface/SimpleTransmission</type>
      <joint name="front_right_hip_x">
         <hardwareInterface>hardware_interface/EffortJointInterface</hardwareInterface>
      </joint>
      <actuator name="front_right_hip_x_actuator">
         <hardwareInterface>hardware_interface/EffortJointInterface</hardwareInterface>
         <mechanicalReduction>1</mechanicalReduction>
      </actuator>
   </transmission>
   <transmission name="front_right_hip_y_trans">
      <type>transmission_interface/SimpleTransmission</type>
      <joint name="front_right_hip_y">
         <hardwareInterface>hardware_interface/EffortJointInterface</hardwareInterface>
      </joint>
      <actuator name="front_right_hip_y_actuator">
         <hardwareInterface>hardware_interface/EffortJointInterface</hardwareInterface>
         <mechanicalReduction>1</mechanicalReduction>
      </actuator>
   </transmission>
   <transmission name="front_right_knee_trans">
      <type>transmission_interface/SimpleTransmission</type>
      <joint name="front_right_knee">
         <hardwareInterface>hardware_interface/EffortJointInterface</hardwareInterface>
      </joint>
      <actuator name="front_right_knee_actuator">
         <hardwareInterface>hardware_interface/EffortJointInterface</hardwareInterface>
         <mechanicalReduction>1</mechanicalReduction>
      </actuator>
   </transmission>
   <link name="rear_left_hip">
      <visual>
         <geometry>
            <mesh filename="meshes/rear_left_hip.dae" />
         </geometry>
      </visual>
      <collision>
         <geometry>
            <mesh filename="meshes/rear_left_hip_collision.stl" />
         </geometry>
      </collision>
      <inertial>
         <mass value="2.0" />
         <inertia ixx="0.0027" ixy="0.0" ixz="0.0" iyy="0.00416666666667" iyz="0.0" izz="0.00416666666667" />
      </inertial>
   </link>
   <joint name="rear_left_hip_x" type="revolute">
      <origin rpy="0 0 0" xyz="-0.29785 0.055 0" />
      <axis xyz="1 0 0" />
      <parent link="body" />
      <child link="rear_left_hip" />
      <limit effort="100" lower="-0.78539816339744827899" upper="0.78539816339744827899" velocity="1000.00" />
   </joint>
   <link name="rear_left_upper_leg">
      <visual>
         <geometry>
            <mesh filename="meshes/rear_left_upper_leg.dae" />
         </geometry>
      </visual>
      <collision>
         <geometry>
            <mesh filename="meshes/rear_left_upper_leg_collision.stl" />
         </geometry>
      </collision>
      <inertial>
         <origin rpy="0 0 0" xyz="0 0 -0.14" />
         <mass value="1.0" />
         <inertia ixx="0.0155334166667" ixy="0.0" ixz="0.0" iyy="0.0155334166667" iyz="0.0" izz="0.000962666666667" />
      </inertial>
   </link>
   <joint name="rear_left_hip_y" type="revolute">
      <origin rpy="0 0 0" xyz="0 0.110945 0" />
      <axis xyz="0 1 0" />
      <parent link="rear_left_hip" />
      <child link="rear_left_upper_leg" />
      <limit effort="100" lower="-0.89884456477707963539" upper="2.2951079663725435509" velocity="1000.00" />
   </joint>
   <link name="rear_left_lower_leg">
      <visual>
         <geometry>
            <mesh filename="meshes/rear_left_lower_leg.dae" />
         </geometry>
      </visual>
      <collision>
         <geometry>
            <mesh filename="meshes/rear_left_lower_leg_collision.stl" scale="0.82 0.97 0.98" />
         </geometry>
      </collision>
      <inertial>
         <origin rpy="0 0 0" xyz="0 0 -0.16" />
         <mass value="0.5" />
         <inertia ixx="0.007434375" ixy="0.0" ixz="0.0" iyy="0.00740104166667" iyz="0.0" izz="0.000135416666667" />
      </inertial>
   </link>
   <gazebo reference="rear_left_lower_leg">
      <kp>100000.0</kp>
      <kd>1.0</kd>
      <mu1>0.8</mu1>
      <mu2>0.8</mu2>
      <maxVel>0.0</maxVel>
      <minDepth>0.001</minDepth>
   </gazebo>
   <joint name="rear_left_knee" type="revolute">
      <origin rpy="0 0 0" xyz="0.025 0 -0.3205" />
      <axis xyz="0 1 0" />
      <parent link="rear_left_upper_leg" />
      <child link="rear_left_lower_leg" />
      <limit effort="100" lower="-2.7929" upper="-0.254801" velocity="1000.00" />
   </joint>
   <link name="rear_left_ee" />
   <joint name="rear_left_foot" type="fixed">
      <parent link="rear_left_lower_leg" />
      <child link="rear_left_ee" />
      <origin rpy="0 0 0" xyz="0 0 -0.37" />
   </joint>
   <transmission name="rear_left_hip_x_trans">
      <type>transmission_interface/SimpleTransmission</type>
      <joint name="rear_left_hip_x">
         <hardwareInterface>hardware_interface/EffortJointInterface</hardwareInterface>
      </joint>
      <actuator name="rear_left_hip_x_actuator">
         <hardwareInterface>hardware_interface/EffortJointInterface</hardwareInterface>
         <mechanicalReduction>1</mechanicalReduction>
      </actuator>
   </transmission>
   <transmission name="rear_left_hip_y_trans">
      <type>transmission_interface/SimpleTransmission</type>
      <joint name="rear_left_hip_y">
         <hardwareInterface>hardware_interface/EffortJointInterface</hardwareInterface>
      </joint>
      <actuator name="rear_left_hip_y_actuator">
         <hardwareInterface>hardware_interface/EffortJointInterface</hardwareInterface>
         <mechanicalReduction>1</mechanicalReduction>
      </actuator>
   </transmission>
   <transmission name="rear_left_knee_trans">
      <type>transmission_interface/SimpleTransmission</type>
      <joint name="rear_left_knee">
         <hardwareInterface>hardware_interface/EffortJointInterface</hardwareInterface>
      </joint>
      <actuator name="rear_left_knee_actuator">
         <hardwareInterface>hardware_interface/EffortJointInterface</hardwareInterface>
         <mechanicalReduction>1</mechanicalReduction>
      </actuator>
   </transmission>
   <link name="rear_right_hip">
      <visual>
         <geometry>
            <mesh filename="meshes/rear_right_hip.dae" />
         </geometry>
      </visual>
      <collision>
         <geometry>
            <mesh filename="meshes/rear_right_hip_collision.stl" />
         </geometry>
      </collision>
      <inertial>
         <mass value="2.0" />
         <inertia ixx="0.0027" ixy="0.0" ixz="0.0" iyy="0.00416666666667" iyz="0.0" izz="0.00416666666667" />
      </inertial>
   </link>
   <joint name="rear_right_hip_x" type="revolute">
      <origin rpy="0 0 0" xyz="-0.29785 -0.055 0" />
      <axis xyz="1 0 0" />
      <parent link="body" />
      <child link="rear_right_hip" />
      <limit effort="100" lower="-0.78539816339744827899" upper="0.78539816339744827899" velocity="1000.00" />
   </joint>
   <link name="rear_right_upper_leg">
      <visual>
         <geometry>
            <mesh filename="meshes/rear_right_upper_leg.dae" />
         </geometry>
      </visual>
      <collision>
         <geometry>
            <mesh filename="meshes/rear_right_upper_leg_collision.stl" />
         </geometry>
      </collision>
      <inertial>
         <origin rpy="0 0 0" xyz="0 0 -0.14" />
         <mass value="1.0" />
         <inertia ixx="0.0155334166667" ixy="0.0" ixz="0.0" iyy="0.0155334166667" iyz="0.0" izz="0.000962666666667" />
      </inertial>
   </link>
   <joint name="rear_right_hip_y" type="revolute">
      <origin rpy="0 0 0" xyz="0 -0.110945 0" />
      <axis xyz="0 1 0" />
      <parent link="rear_right_hip" />
      <child link="rear_right_upper_leg" />
      <limit effort="100" lower="-0.89884456477707963539" upper="2.2951079663725435509" velocity="1000.00" />
   </joint>
   <link name="rear_right_lower_leg">
      <visual>
         <geometry>
            <mesh filename="meshes/rear_right_lower_leg.dae" />
         </geometry>
      </visual>
      <collision>
         <geometry>
            <mesh filename="meshes/rear_right_lower_leg_collision.stl" scale="0.82 0.97 0.98" />
         </geometry>
      </collision>
      <inertial>
         <origin rpy="0 0 0" xyz="0 0 -0.16" />
         <mass value="0.5" />
         <inertia ixx="0.007434375" ixy="0.0" ixz="0.0" iyy="0.00740104166667" iyz="0.0" izz="0.000135416666667" />
      </inertial>
   </link>
   <gazebo reference="rear_right_lower_leg">
      <kp>100000.0</kp>
      <kd>1.0</kd>
      <mu1>0.8</mu1>
      <mu2>0.8</mu2>
      <maxVel>0.0</maxVel>
      <minDepth>0.001</minDepth>
   </gazebo>
   <joint name="rear_right_knee" type="revolute">
      <origin rpy="0 0 0" xyz="0.025 0 -0.3205" />
      <axis xyz="0 1 0" />
      <parent link="rear_right_upper_leg" />
      <child link="rear_right_lower_leg" />
      <limit effort="100" lower="-2.7929" upper="-0.254801" velocity="1000.00" />
   </joint>
   <link name="rear_right_ee" />
   <joint name="rear_right_foot" type="fixed">
      <parent link="rear_right_lower_leg" />
      <child link="rear_right_ee" />
      <origin rpy="0 0 0" xyz="0 0 -0.37" />
   </joint>
   <transmission name="rear_right_hip_x_trans">
      <type>transmission_interface/SimpleTransmission</type>
      <joint name="rear_right_hip_x">
         <hardwareInterface>hardware_interface/EffortJointInterface</hardwareInterface>
      </joint>
      <actuator name="rear_right_hip_x_actuator">
         <hardwareInterface>hardware_interface/EffortJointInterface</hardwareInterface>
         <mechanicalReduction>1</mechanicalReduction>
      </actuator>
   </transmission>
   <transmission name="rear_right_hip_y_trans">
      <type>transmission_interface/SimpleTransmission</type>
      <joint name="rear_right_hip_y">
         <hardwareInterface>hardware_interface/EffortJointInterface</hardwareInterface>
      </joint>
      <actuator name="rear_right_hip_y_actuator">
         <hardwareInterface>hardware_interface/EffortJointInterface</hardwareInterface>
         <mechanicalReduction>1</mechanicalReduction>
      </actuator>
   </transmission>
   <transmission name="rear_right_knee_trans">
      <type>transmission_interface/SimpleTransmission</type>
      <joint name="rear_right_knee">
         <hardwareInterface>hardware_interface/EffortJointInterface</hardwareInterface>
      </joint>
      <actuator name="rear_right_knee_actuator">
         <hardwareInterface>hardware_interface/EffortJointInterface</hardwareInterface>
         <mechanicalReduction>1</mechanicalReduction>
      </actuator>
   </transmission>
   <gazebo>
      <plugin filename="libgazebo_ros_p3d.so" name="p3d_base_controller">
         <alwaysOn>true</alwaysOn>
         <updateRate>10.0</updateRate>
         <bodyName>base_link</bodyName>
         <topicName>odom/ground_truth</topicName>
         <gaussianNoise>0.01</gaussianNoise>
         <frameName>world</frameName>
         <xyzOffsets>0 0 0</xyzOffsets>
         <rpyOffsets>0 0 0</rpyOffsets>
      </plugin>
   </gazebo>
   <gazebo>
      <plugin filename="libgazebo_ros_control.so" name="gazebo_ros_control">
         <legacyModeNS>true</legacyModeNS>
      </plugin>
   </gazebo>
</robot>